Workbook

Sheet Log
A1: Log
A2: Hole ID | B2: Planned Hole ID | C2: Pit | D2: Sub Pit | E2: Coordinate System | F2: Planned collar X (m) | G2: Planned collar Y (m) | H2: Planned collar Z (m) | I2: Planned collar trend (°) | J2: Planned collar plunge (°) | K2: Planned length (m) | L2: Surveyed collar X - East (m) | M2: Surveyed collar Y - North (m) | N2: Surveyed collar Z (m) | O2: Collar Trend (°) | P2: Collar Plunge (°) | Q2: Logged depth from (m) | R2: Logged depth to (m) | S2: Logged Length (m) | T2: Core size | U2: Logged date | V2: Logged by | W2: Oriented core | X2: Orientation marker | Y2: Comments
A3: COG-25-08 | B3: CGF-01 | C3: Courvan Nord Bussière | F3: 311130 | G3: 5334390 | H3: 322.9 | I3: 169.9 | J3: -56 | K3: 183 | S3: =Data_Log[[#This Row],[Logged depth to (m)]]-Data_Log[[#This Row],[Logged depth from (m)]] -> 0 | T3: HQ
A4: COG-25-10 | B4: CGF-02 | C4: Courvan Nord Bussière | F4: 311005 | G4: 5334645 | H4: 316.1 | I4: 45 | J4: -70 | K4: 150 | S4: =Data_Log[[#This Row],[Logged depth to (m)]]-Data_Log[[#This Row],[Logged depth from (m)]] -> 0 | T4: HQ
A5: COG-25-11 | B5: CGF-03 | C5: Courvan Nord Bussière | F5: 310913 | G5: 5334584 | H5: 315.6 | I5: 225 | J5: -70 | K5: 150 | S5: =Data_Log[[#This Row],[Logged depth to (m)]]-Data_Log[[#This Row],[Logged depth from (m)]] -> 0 | T5: HQ
A6: COG-25-09 | B6: CGF-04 | C6: Courvan Nord Bussière | F6: 311203 | G6: 5334518 | H6: 321.6 | I6: 100 | J6: -56 | K6: 115 | S6: =Data_Log[[#This Row],[Logged depth to (m)]]-Data_Log[[#This Row],[Logged depth from (m)]] -> 0 | T6: HQ
A7: COG-25-12 | B7: CGF-05 | C7: Courvan Nord Creek Zone | F7: 310894 | G7: 5335177 | H7: 308.3 | I7: 11 | J7: -60 | K7: 120 | S7: =Data_Log[[#This Row],[Logged depth to (m)]]-Data_Log[[#This Row],[Logged depth from (m)]] -> 0 | T7: HQ
A8: CGF-06 | B8: CGF-06 - Annulé | S8: =Data_Log[[#This Row],[Logged depth to (m)]]-Data_Log[[#This Row],[Logged depth from (m)]] -> 0 | T8: HQ
A9: COG-25-07 | B9: CGF-07 | C9: Courvan South | F9: 310428 | G9: 5333627 | H9: 331.7 | I9: 355 | J9: -75 | K9: 300 | S9: =Data_Log[[#This Row],[Logged depth to (m)]]-Data_Log[[#This Row],[Logged depth from (m)]] -> 0 | T9: HQ
A10: COG-25-06 | B10: CGF-08 | C10: Courvan South | F10: 310438 | G10: 5333481 | H10: 333.8 | I10: 180 | J10: -75 | K10: 135 | S10: =Data_Log[[#This Row],[Logged depth to (m)]]-Data_Log[[#This Row],[Logged depth from (m)]] -> 0 | T10: HQ
S11: =Data_Log[[#This Row],[Logged depth to (m)]]-Data_Log[[#This Row],[Logged depth from (m)]] -> 0
S12: =Data_Log[[#This Row],[Logged depth to (m)]]-Data_Log[[#This Row],[Logged depth from (m)]] -> 0
S13: =Data_Log[[#This Row],[Logged depth to (m)]]-Data_Log[[#This Row],[Logged depth from (m)]] -> 0
S14: =Data_Log[[#This Row],[Logged depth to (m)]]-Data_Log[[#This Row],[Logged depth from (m)]] -> 0
S15: =Data_Log[[#This Row],[Logged depth to (m)]]-Data_Log[[#This Row],[Logged depth from (m)]] -> 0
S16: =Data_Log[[#This Row],[Logged depth to (m)]]-Data_Log[[#This Row],[Logged depth from (m)]] -> 0
S17: =Data_Log[[#This Row],[Logged depth to (m)]]-Data_Log[[#This Row],[Logged depth from (m)]] -> 0
S18: =Data_Log[[#This Row],[Logged depth to (m)]]-Data_Log[[#This Row],[Logged depth from (m)]] -> 0
S19: =Data_Log[[#This Row],[Logged depth to (m)]]-Data_Log[[#This Row],[Logged depth from (m)]] -> 0
S20: =Data_Log[[#This Row],[Logged depth to (m)]]-Data_Log[[#This Row],[Logged depth from (m)]] -> 0
S21: =Data_Log[[#This Row],[Logged depth to (m)]]-Data_Log[[#This Row],[Logged depth from (m)]] -> 0
S22: =Data_Log[[#This Row],[Logged depth to (m)]]-Data_Log[[#This Row],[Logged depth from (m)]] -> 0
... S38: =Data_Log[[#This Row],[Logged depth to (m)]]-Data_Log[[#This Row],[Logged depth from (m)]] -> 0

Sheet Survey
A1: Survey
A3: Hole ID | B3: Planned Hole ID | C3: Depth (m) | D3: Dip (deg) | E3: Azimuth (deg) | F3: Comments | G3: QA/QC Dip Planned | H3: QA/QC Azimut Planned | I3: Dip Planned - Surveyed | J3: Azimut Planned - Surveyed2
B4: =VLOOKUP(Tableau26[[#This Row],[Hole ID]],Data_Log[],2,FALSE) -> #N/A | G4: =_xlfn.XLOOKUP(Tableau26[[#This Row],[Hole ID]],Data_Log[Hole ID],Data_Log[Planned collar plunge (°)]) -> 0 | H4: =_xlfn.XLOOKUP(Tableau26[[#This Row],[Hole ID]],Data_Log[Hole ID],Data_Log[Planned collar trend (°)]) -> 0 | I4: =Tableau26[[#This Row],[Dip (deg)]]-Tableau26[[#This Row],[QA/QC Dip Planned]] -> 0 | J4: =Tableau26[[#This Row],[Azimuth (deg)]]-Tableau26[[#This Row],[QA/QC Azimut Planned]] -> 0
B5: =VLOOKUP(Tableau26[[#This Row],[Hole ID]],Data_Log[],2,FALSE) -> #N/A | G5: =_xlfn.XLOOKUP(Tableau26[[#This Row],[Hole ID]],Data_Log[Hole ID],Data_Log[Planned collar plunge (°)]) -> 0 | H5: =_xlfn.XLOOKUP(Tableau26[[#This Row],[Hole ID]],Data_Log[Hole ID],Data_Log[Planned collar trend (°)]) -> 0 | I5: =Tableau26[[#This Row],[Dip (deg)]]-Tableau26[[#This Row],[QA/QC Dip Planned]] -> 0 | J5: =Tableau26[[#This Row],[Azimuth (deg)]]-Tableau26[[#This Row],[QA/QC Azimut Planned]] -> 0
B6: =VLOOKUP(Tableau26[[#This Row],[Hole ID]],Data_Log[],2,FALSE) -> #N/A | G6: =_xlfn.XLOOKUP(Tableau26[[#This Row],[Hole ID]],Data_Log[Hole ID],Data_Log[Planned collar plunge (°)]) -> 0 | H6: =_xlfn.XLOOKUP(Tableau26[[#This Row],[Hole ID]],Data_Log[Hole ID],Data_Log[Planned collar trend (°)]) -> 0 | I6: =Tableau26[[#This Row],[Dip (deg)]]-Tableau26[[#This Row],[QA/QC Dip Planned]] -> 0 | J6: =Tableau26[[#This Row],[Azimuth (deg)]]-Tableau26[[#This Row],[QA/QC Azimut Planned]] -> 0
B7: =VLOOKUP(Tableau26[[#This Row],[Hole ID]],Data_Log[],2,FALSE) -> #N/A | G7: =_xlfn.XLOOKUP(Tableau26[[#This Row],[Hole ID]],Data_Log[Hole ID],Data_Log[Planned collar plunge (°)]) -> 0 | H7: =_xlfn.XLOOKUP(Tableau26[[#This Row],[Hole ID]],Data_Log[Hole ID],Data_Log[Planned collar trend (°)]) -> 0 | I7: =Tableau26[[#This Row],[Dip (deg)]]-Tableau26[[#This Row],[QA/QC Dip Planned]] -> 0 | J7: =Tableau26[[#This Row],[Azimuth (deg)]]-Tableau26[[#This Row],[QA/QC Azimut Planned]] -> 0
B8: =VLOOKUP(Tableau26[[#This Row],[Hole ID]],Data_Log[],2,FALSE) -> #N/A | G8: =_xlfn.XLOOKUP(Tableau26[[#This Row],[Hole ID]],Data_Log[Hole ID],Data_Log[Planned collar plunge (°)]) -> 0 | H8: =_xlfn.XLOOKUP(Tableau26[[#This Row],[Hole ID]],Data_Log[Hole ID],Data_Log[Planned collar trend (°)]) -> 0 | I8: =Tableau26[[#This Row],[Dip (deg)]]-Tableau26[[#This Row],[QA/QC Dip Planned]] -> 0 | J8: =Tableau26[[#This Row],[Azimuth (deg)]]-Tableau26[[#This Row],[QA/QC Azimut Planned]] -> 0
B9: =VLOOKUP(Tableau26[[#This Row],[Hole ID]],Data_Log[],2,FALSE) -> #N/A | G9: =_xlfn.XLOOKUP(Tableau26[[#This Row],[Hole ID]],Data_Log[Hole ID],Data_Log[Planned collar plunge (°)]) -> 0 | H9: =_xlfn.XLOOKUP(Tableau26[[#This Row],[Hole ID]],Data_Log[Hole ID],Data_Log[Planned collar trend (°)]) -> 0 | I9: =Tableau26[[#This Row],[Dip (deg)]]-Tableau26[[#This Row],[QA/QC Dip Planned]] -> 0 | J9: =Tableau26[[#This Row],[Azimuth (deg)]]-Tableau26[[#This Row],[QA/QC Azimut Planned]] -> 0
B10: =VLOOKUP(Tableau26[[#This Row],[Hole ID]],Data_Log[],2,FALSE) -> #N/A | G10: =_xlfn.XLOOKUP(Tableau26[[#This Row],[Hole ID]],Data_Log[Hole ID],Data_Log[Planned collar plunge (°)]) -> 0 | H10: =_xlfn.XLOOKUP(Tableau26[[#This Row],[Hole ID]],Data_Log[Hole ID],Data_Log[Planned collar trend (°)]) -> 0 | I10: =Tableau26[[#This Row],[Dip (deg)]]-Tableau26[[#This Row],[QA/QC Dip Planned]] -> 0 | J10: =Tableau26[[#This Row],[Azimuth (deg)]]-Tableau26[[#This Row],[QA/QC Azimut Planned]] -> 0
B11: =VLOOKUP(Tableau26[[#This Row],[Hole ID]],Data_Log[],2,FALSE) -> #N/A | G11: =_xlfn.XLOOKUP(Tableau26[[#This Row],[Hole ID]],Data_Log[Hole ID],Data_Log[Planned collar plunge (°)]) -> 0 | H11: =_xlfn.XLOOKUP(Tableau26[[#This Row],[Hole ID]],Data_Log[Hole ID],Data_Log[Planned collar trend (°)]) -> 0 | I11: =Tableau26[[#This Row],[Dip (deg)]]-Tableau26[[#This Row],[QA/QC Dip Planned]] -> 0 | J11: =Tableau26[[#This Row],[Azimuth (deg)]]-Tableau26[[#This Row],[QA/QC Azimut Planned]] -> 0
B12: =VLOOKUP(Tableau26[[#This Row],[Hole ID]],Data_Log[],2,FALSE) -> #N/A | G12: =_xlfn.XLOOKUP(Tableau26[[#This Row],[Hole ID]],Data_Log[Hole ID],Data_Log[Planned collar plunge (°)]) -> 0 | H12: =_xlfn.XLOOKUP(Tableau26[[#This Row],[Hole ID]],Data_Log[Hole ID],Data_Log[Planned collar trend (°)]) -> 0 | I12: =Tableau26[[#This Row],[Dip (deg)]]-Tableau26[[#This Row],[QA/QC Dip Planned]] -> 0 | J12: =Tableau26[[#This Row],[Azimuth (deg)]]-Tableau26[[#This Row],[QA/QC Azimut Planned]] -> 0
B13: =VLOOKUP(Tableau26[[#This Row],[Hole ID]],Data_Log[],2,FALSE) -> #N/A | G13: =_xlfn.XLOOKUP(Tableau26[[#This Row],[Hole ID]],Data_Log[Hole ID],Data_Log[Planned collar plunge (°)]) -> 0 | H13: =_xlfn.XLOOKUP(Tableau26[[#This Row],[Hole ID]],Data_Log[Hole ID],Data_Log[Planned collar trend (°)]) -> 0 | I13: =Tableau26[[#This Row],[Dip (deg)]]-Tableau26[[#This Row],[QA/QC Dip Planned]] -> 0 | J13: =Tableau26[[#This Row],[Azimuth (deg)]]-Tableau26[[#This Row],[QA/QC Azimut Planned]] -> 0
B14: =VLOOKUP(Tableau26[[#This Row],[Hole ID]],Data_Log[],2,FALSE) -> #N/A | G14: =_xlfn.XLOOKUP(Tableau26[[#This Row],[Hole ID]],Data_Log[Hole ID],Data_Log[Planned collar plunge (°)]) -> 0 | H14: =_xlfn.XLOOKUP(Tableau26[[#This Row],[Hole ID]],Data_Log[Hole ID],Data_Log[Planned collar trend (°)]) -> 0 | I14: =Tableau26[[#This Row],[Dip (deg)]]-Tableau26[[#This Row],[QA/QC Dip Planned]] -> 0 | J14: =Tableau26[[#This Row],[Azimuth (deg)]]-Tableau26[[#This Row],[QA/QC Azimut Planned]] -> 0
B15: =VLOOKUP(Tableau26[[#This Row],[Hole ID]],Data_Log[],2,FALSE) -> #N/A | G15: =_xlfn.XLOOKUP(Tableau26[[#This Row],[Hole ID]],Data_Log[Hole ID],Data_Log[Planned collar plunge (°)]) -> 0 | H15: =_xlfn.XLOOKUP(Tableau26[[#This Row],[Hole ID]],Data_Log[Hole ID],Data_Log[Planned collar trend (°)]) -> 0 | I15: =Tableau26[[#This Row],[Dip (deg)]]-Tableau26[[#This Row],[QA/QC Dip Planned]] -> 0 | J15: =Tableau26[[#This Row],[Azimuth (deg)]]-Tableau26[[#This Row],[QA/QC Azimut Planned]] -> 0
... B346: =VLOOKUP(Tableau26[[#This Row],[Hole ID]],Data_Log[],2,FALSE) -> #N/A | G346: =_xlfn.XLOOKUP(Tableau26[[#This Row],[Hole ID]],Data_Log[Hole ID],Data_Log[Planned collar plunge (°)]) -> 0 | H346: =_xlfn.XLOOKUP(Tableau26[[#This Row],[Hole ID]],Data_Log[Hole ID],Data_Log[Planned collar trend (°)]) -> 0 | I346: =Tableau26[[#This Row],[Dip (deg)]]-Tableau26[[#This Row],[QA/QC Dip Planned]] -> 0 | J346: =Tableau26[[#This Row],[Azimuth (deg)]]-Tableau26[[#This Row],[QA/QC Azimut Planned]] -> 0

Sheet Geotech
A1: Geotech
AB2: RMR | AN2: GSI | AO2: Q
A3: Hole ID | B3: Planned Hole ID | C3: From (m) | D3: To (m) | E3: Mid Point (m) | F3: Run (m) | G3: TCR (m) | H3: TCR (%) | I3: TCR Reel (m) | J3: Run Reel (m) | K3: RQD (m) | L3: RQD (%) | M3: Lithology (when logging on site) | N3: Lithology | O3: Weathering/Alteration | P3: Field Intact Rock Strength | Q3: Micro-Defects | R3: Fault (m) | S3: Broken Core (m) | T3: Lost Core (m) | U3: Disking (m) | V3: Fracture per interval | W3: Validation fracture per interval | X3: Joint Set Rating | Y3: Gamma angle | Z3: Comments | AA3: x | AB3: Added fractures (BC, FLT, LC) | AC3: Joint spacing (m) | AD3: Is50_1 | AE3: Is50_2 | AF3: Is50_3 | AG3: Is50 | AH3: RMR76 - Strength rating | AI3: RMR76 - RQD rating | AJ3: RMR76 - Joint spacing rating | AK3: RMR76 - Joint condition rating | AL3: RMR76 - Ground water rating | AM3: RMR76 | AN3: GSI | AO3: Jn rating | AP3: Jr/Ja | AQ3: Jw/SRF | AR3: Q' | AS3: Q | AT3: x2 | AU3: Transformed RQD (%) | AV3: Transformed TCR (%) | AW3: Fracture Frequency (#/m) | AX3: FIRS Code | AY3: Transformed FIRS Code | AZ3: FIRS Min UCS (MPa) | BA3: FIRS Avg UCS (MPa) | BB3: FIRS Max UCS (MPa) | BC3: Transformed RMR76 | BD3: Altered-Weathered Code
A4: COG-25-08 | B4: =VLOOKUP(Data_Geotech[[#This Row],[Hole ID]],Data_Log[],2,FALSE) -> CGF-01 | C4: 50 | D4: 50.98 | E4: =(Data_Geotech[[#This Row],[To (m)]]-Data_Geotech[[#This Row],[From (m)]])/2+Data_Geotech[[#This Row],[From (m)]] -> 50.49 | F4: =Data_Geotech[[#This Row],[To (m)]]-Data_Geotech[[#This Row],[From (m)]] -> 0.98 | G4: 0.98 | H4: =Data_Geotech[[#This Row],[TCR (m)]]/Data_Geotech[[#This Row],[Run (m)]]*100 -> 100 | I4: 0.98 | J4: 0.98 | K4: 0.98 | L4: =Data_Geotech[[#This Row],[RQD (m)]]/Data_Geotech[[#This Row],[Run Reel (m)]]*100 -> 100 | M4: Diorite | O4: W1/A1 - Fresh | P4: R5 - Very strong | Q4: 1 - Weak | V4: 1 | W4: =SUMIFS(Discontinuities!$D$4:$D$9664,Discontinuities!$A$4:$A$9664,A4,Discontinuities!$C$4:$C$9664,">="&C4,Discontinuities!$C$4:$C$9664,"<"&D4) -SUMIFS(Discontinuities!$D$4:$D$9664,Discontinuities!$A$4:$A$9664,A4,Discontinuities!$C$4:$C$9664,">="&C4,Discontinuities!$C$4:$C$9664,"<"&D4,Discontinuities!$E$4:$E$9664,"=BC") -SUMIFS(Discontinuities!$D$4:$D$9664,Discontinuities!$A$4:$A$9664,A4,Discontinuities!$C$4:$C$9664,">="&C4,Discontinuities!$C$4:$C$9664,"<"&D4,Discontinuities!$E$4:$E$9664,"=LC") -SUMIFS(Discontinuities!$D$4:$D$9664,Discontinuities!$A$4:$A$9664,A4,Discontinuities!$C$4:$C$9664,">="&C4,Discontinuities!$C$4:$C$9664,"<"&D4,Discontinuities!$E$4:$E$9664,"=FLT") -> 1 | X4: 1 - Massive or few joints | AB4: =IFERROR(ROUND((Data_Geotech[[#This Row],[Fault (m)]]+Data_Geotech[[#This Row],[Broken Core (m)]]+Data_Geotech[[#This Row],[Lost Core (m)]])*30,0),0) -> 0 | AC4: =IF(Data_Geotech[[#This Row],[Added fractures (BC, FLT, LC)]]+Data_Geotech[[#This Row],[Fracture per interval]]=0,99,1/((Data_Geotech[[#This Row],[Fracture per interval]]+Data_Geotech[[#This Row],[Added fractures (BC, FLT, LC)]])/Data_Geotech[[#This Row],[Run (m)]])) -> 0.98 | AD4: {=IFERROR(_xlfn.XLOOKUP(1,(A4=PLT!$A$4:$A$8886)*(Geotech!C4<=PLT!$F$4:$F$8886)*(Geotech!D4>=PLT!$F$4:$F$8886)*("Valid"=PLT!$P$4:$P$8886),PLT!$V$4:$V$8886),"")} -> 0 | AE4: {=IFERROR(_xlfn.XLOOKUP(1,(A4=PLT!$A$4:$A$8886)*(Geotech!C4<=PLT!$F$4:$F$8886)*(Geotech!D4>=PLT!$F$4:$F$8886)*(PLT!$V$4:$V$8886<>AD4)*("Valid"=PLT!$P$4:$P$7190),PLT!$V$4:$V$8886),"")} | AF4: {=IFERROR(_xlfn.XLOOKUP(1,(A4=PLT!$A$4:$A$8886)*(Geotech!C4<=PLT!$F$4:$F$8886)*(Geotech!D4>=PLT!$F$4:$F$8886)*(PLT!$V$4:$V$8886<>AD4)*(PLT!$V$4:$V$8886<>AE4)*("Valid"=PLT!$P$4:$P$7190),PLT!$V$4:$V$8886),"")} | AG4: =IFERROR(IF(AVERAGE(AD4:AF4)>References!$BO$23,References!$BP$23, IF(AVERAGE(AD4:AF4)>References!$BO$22,References!$BP$22, IF(AVERAGE(AD4:AF4)>References!$BO$21,References!$BP$21, IF(AVERAGE(AD4:AF4)>References!$BO$20,References!$BP$20, IF(AVERAGE(AD4:AF4)>References!$BO$19,References!$BP$19, IF(AVERAGE(AD4:AF4)>References!$BO$18,References!$BP$18, 0)))))),"") -> 0 | AH4: =IF(Data_Geotech[[#This Row],[Is50]]="",VLOOKUP(Data_Geotech[[#This Row],[Field Intact Rock Strength]],Table_RMR76_Strength[],2,FALSE),Data_Geotech[[#This Row],[Is50]]) -> 0 | AI4: =IF(Data_Geotech[[#This Row],[RQD (%)]]<=25,3,IF(Data_Geotech[[#This Row],[RQD (%)]]<=50,8,IF(Data_Geotech[[#This Row],[RQD (%)]]<=75,13,IF(Data_Geotech[[#This Row],[RQD (%)]]<=90,17,20)))) -> 20 | AJ4: =IF(Data_Geotech[[#This Row],[Joint spacing (m)]]<=0.05,5,IF(Data_Geotech[[#This Row],[Joint spacing (m)]]<=0.3,10,IF(Data_Geotech[[#This Row],[Joint spacing (m)]]<=1,20,IF(Data_Geotech[[#This Row],[Joint spacing (m)]]<=3,25,30)))) -> 20 | AK4: =IFERROR(AVERAGEIFS(Data_Discontinuities[[#All],[JCR]],Data_Discontinuities[[#All],[Hole ID]],"="&Data_Geotech[[#This Row],[Hole ID]],Data_Discontinuities[[#All],[Depth (m)]],">="&Data_Geotech[[#This Row],[From (m)]],Data_Discontinuities[[#All],[Depth (m)]],"<"&Data_Geotech[[#This Row],[To (m)]]),IF(Data_Geotech[[#This Row],[Added fractures (BC, FLT, LC)]]=0,IF(Data_Geotech[[#This Row],[Fracture per interval]]=0,25,6),6)) -> 25 | AL4: 10 | AM4: =IF(Data_Geotech[[#This Row],[FIRS Code]]="R",IFERROR(SUM(Data_Geotech[[#This Row],[RMR76 - Strength rating]:[RMR76 - Ground water rating]]),""),"") -> 75 | AN4: =IF(Data_Geotech[[#This Row],[FIRS Code]]="R",(2*Data_Geotech[[#This Row],[RMR76 - Joint condition rating]])+(IF(Data_Geotech[[#This Row],[RQD (%)]]>80,80/2,Data_Geotech[[#This Row],[RQD (%)]]/2)),"") -> 90 | AO4: =LEFT(Data_Geotech[[#This Row],[Joint Set Rating]],FIND("-",Data_Geotech[[#This Row],[Joint Set Rating]],1)-2) -> 1 | AP4: =IFERROR(AVERAGEIFS(Data_Discontinuities[[#All],[Jr/Ja]],Data_Discontinuities[[#All],[Hole ID]],"="&Data_Geotech[[#This Row],[Hole ID]],Data_Discontinuities[[#All],[Depth (m)]],">="&Data_Geotech[[#This Row],[From (m)]],Data_Discontinuities[[#All],[Depth (m)]],"<"&Data_Geotech[[#This Row],[To (m)]]),IF(Data_Geotech[[#This Row],[Added fractures (BC, FLT, LC)]]>Data_Geotech[[#This Row],[Fracture per interval]],1/4,IF(Data_Geotech[[#This Row],[Fracture per interval]]=0,4/0.75,"ERROR: should never happen!"))) -> 3 | AQ4: =1/1 -> 1 | AR4: =IF(Data_Geotech[[#This Row],[FIRS Code]]="R",IFERROR((IF(Data_Geotech[[#This Row],[RQD (%)]]<10,10,Data_Geotech[[#This Row],[RQD (%)]])/Data_Geotech[[#This Row],[Jn rating]])*Data_Geotech[[#This Row],[Jr/Ja]],""),"") -> 300 | AS4: =IF(Data_Geotech[[#This Row],[FIRS Code]]="R",IFERROR((IF(Data_Geotech[[#This Row],[RQD (%)]]<10,10,Data_Geotech[[#This Row],[RQD (%)]])/Data_Geotech[[#This Row],[Jn rating]])*Data_Geotech[[#This Row],[Jr/Ja]]*Data_Geotech[[#This Row],[Jw/SRF]],""),"") -> 300 | AU4: =100-Data_Geotech[[#This Row],[RQD (%)]] -> 0 | AV4: =100-Data_Geotech[[#This Row],[TCR (%)]] -> -3.126388e-13 | AW4: =(Data_Geotech[[#This Row],[Fracture per interval]]+Data_Geotech[[#This Row],[Added fractures (BC, FLT, LC)]])/Data_Geotech[[#This Row],[TCR (m)]] -> 1.0204082 | AX4: R | AY4: =7-MID(Data_Geotech[[#This Row],[Field Intact Rock Strength]],2,1) -> 2 | AZ4: =VLOOKUP(Data_Geotech[[#This Row],[Field Intact Rock Strength]],Table_FieldStrength[],2,FALSE) -> 100 | BA4: =VLOOKUP(Data_Geotech[[#This Row],[Field Intact Rock Strength]],Table_FieldStrength[],3,FALSE) -> 175 | BB4: =VLOOKUP(Data_Geotech[[#This Row],[Field Intact Rock Strength]],Table_FieldStrength[],4,FALSE) -> 250 | BC4: =100-Data_Geotech[[#This Row],[RMR76]] -> 25 | BD4: =LEFT(Data_Geotech[[#This Row],[Weathering/Alteration]],FIND("-",Data_Geotech[[#This Row],[Weathering/Alteration]])-2) -> W1/A1
A5: COG-25-08 | B5: =VLOOKUP(Data_Geotech[[#This Row],[Hole ID]],Data_Log[],2,FALSE) -> CGF-01 | C5: 50.98 | D5: 52.46 | E5: =(Data_Geotech[[#This Row],[To (m)]]-Data_Geotech[[#This Row],[From (m)]])/2+Data_Geotech[[#This Row],[From (m)]] -> 51.72 | F5: =Data_Geotech[[#This Row],[To (m)]]-Data_Geotech[[#This Row],[From (m)]] -> 1.48 | G5: 1.48 | H5: =Data_Geotech[[#This Row],[TCR (m)]]/Data_Geotech[[#This Row],[Run (m)]]*100 -> 100 | I5: 1.48 | J5: 1.48 | K5: 1.48 | L5: =Data_Geotech[[#This Row],[RQD (m)]]/Data_Geotech[[#This Row],[Run Reel (m)]]*100 -> 100 | M5: Diorite | O5: W1/A1 - Fresh | P5: R6 - Extremely strong | Q5: 2 - Moderate | V5: 2 | W5: =SUMIFS(Discontinuities!$D$4:$D$9664,Discontinuities!$A$4:$A$9664,A5,Discontinuities!$C$4:$C$9664,">="&C5,Discontinuities!$C$4:$C$9664,"<"&D5) -SUMIFS(Discontinuities!$D$4:$D$9664,Discontinuities!$A$4:$A$9664,A5,Discontinuities!$C$4:$C$9664,">="&C5,Discontinuities!$C$4:$C$9664,"<"&D5,Discontinuities!$E$4:$E$9664,"=BC") -SUMIFS(Discontinuities!$D$4:$D$9664,Discontinuities!$A$4:$A$9664,A5,Discontinuities!$C$4:$C$9664,">="&C5,Discontinuities!$C$4:$C$9664,"<"&D5,Discontinuities!$E$4:$E$9664,"=LC") -SUMIFS(Discontinuities!$D$4:$D$9664,Discontinuities!$A$4:$A$9664,A5,Discontinuities!$C$4:$C$9664,">="&C5,Discontinuities!$C$4:$C$9664,"<"&D5,Discontinuities!$E$4:$E$9664,"=FLT") -> 2 | X5: 2 - One joint set | AB5: =IFERROR(ROUND((Data_Geotech[[#This Row],[Fault (m)]]+Data_Geotech[[#This Row],[Broken Core (m)]]+Data_Geotech[[#This Row],[Lost Core (m)]])*30,0),0) -> 0 | AC5: =IF(Data_Geotech[[#This Row],[Added fractures (BC, FLT, LC)]]+Data_Geotech[[#This Row],[Fracture per interval]]=0,99,1/((Data_Geotech[[#This Row],[Fracture per interval]]+Data_Geotech[[#This Row],[Added fractures (BC, FLT, LC)]])/Data_Geotech[[#This Row],[Run (m)]])) -> 0.74 | AD5: {=IFERROR(_xlfn.XLOOKUP(1,(A5=PLT!$A$4:$A$8886)*(Geotech!C5<=PLT!$F$4:$F$8886)*(Geotech!D5>=PLT!$F$4:$F$8886)*("Valid"=PLT!$P$4:$P$8886),PLT!$V$4:$V$8886),"")} -> 0 | AE5: {=IFERROR(_xlfn.XLOOKUP(1,(A5=PLT!$A$4:$A$8886)*(Geotech!C5<=PLT!$F$4:$F$8886)*(Geotech!D5>=PLT!$F$4:$F$8886)*(PLT!$V$4:$V$8886<>AD5)*("Valid"=PLT!$P$4:$P$7190),PLT!$V$4:$V$8886),"")} | AF5: {=IFERROR(_xlfn.XLOOKUP(1,(A5=PLT!$A$4:$A$8886)*(Geotech!C5<=PLT!$F$4:$F$8886)*(Geotech!D5>=PLT!$F$4:$F$8886)*(PLT!$V$4:$V$8886<>AD5)*(PLT!$V$4:$V$8886<>AE5)*("Valid"=PLT!$P$4:$P$7190),PLT!$V$4:$V$8886),"")} | AG5: =IFERROR(IF(AVERAGE(AD5:AF5)>References!$BO$23,References!$BP$23, IF(AVERAGE(AD5:AF5)>References!$BO$22,References!$BP$22, IF(AVERAGE(AD5:AF5)>References!$BO$21,References!$BP$21, IF(AVERAGE(AD5:AF5)>References!$BO$20,References!$BP$20, IF(AVERAGE(AD5:AF5)>References!$BO$19,References!$BP$19, IF(AVERAGE(AD5:AF5)>References!$BO$18,References!$BP$18, 0)))))),"") -> 0 | AH5: =IF(Data_Geotech[[#This Row],[Is50]]="",VLOOKUP(Data_Geotech[[#This Row],[Field Intact Rock Strength]],Table_RMR76_Strength[],2,FALSE),Data_Geotech[[#This Row],[Is50]]) -> 0 | AI5: =IF(Data_Geotech[[#This Row],[RQD (%)]]<=25,3,IF(Data_Geotech[[#This Row],[RQD (%)]]<=50,8,IF(Data_Geotech[[#This Row],[RQD (%)]]<=75,13,IF(Data_Geotech[[#This Row],[RQD (%)]]<=90,17,20)))) -> 20 | AJ5: =IF(Data_Geotech[[#This Row],[Joint spacing (m)]]<=0.05,5,IF(Data_Geotech[[#This Row],[Joint spacing (m)]]<=0.3,10,IF(Data_Geotech[[#This Row],[Joint spacing (m)]]<=1,20,IF(Data_Geotech[[#This Row],[Joint spacing (m)]]<=3,25,30)))) -> 20 | AK5: =IFERROR(AVERAGEIFS(Data_Discontinuities[[#All],[JCR]],Data_Discontinuities[[#All],[Hole ID]],"="&Data_Geotech[[#This Row],[Hole ID]],Data_Discontinuities[[#All],[Depth (m)]],">="&Data_Geotech[[#This Row],[From (m)]],Data_Discontinuities[[#All],[Depth (m)]],"<"&Data_Geotech[[#This Row],[To (m)]]),IF(Data_Geotech[[#This Row],[Added fractures (BC, FLT, LC)]]=0,IF(Data_Geotech[[#This Row],[Fracture per interval]]=0,25,6),6)) -> 25 | AL5: 10 | AM5: =IF(Data_Geotech[[#This Row],[FIRS Code]]="R",IFERROR(SUM(Data_Geotech[[#This Row],[RMR76 - Strength rating]:[RMR76 - Ground water rating]]),""),"") -> 75 | AN5: =IF(Data_Geotech[[#This Row],[FIRS Code]]="R",(2*Data_Geotech[[#This Row],[RMR76 - Joint condition rating]])+(IF(Data_Geotech[[#This Row],[RQD (%)]]>80,80/2,Data_Geotech[[#This Row],[RQD (%)]]/2)),"") -> 90 | AO5: =LEFT(Data_Geotech[[#This Row],[Joint Set Rating]],FIND("-",Data_Geotech[[#This Row],[Joint Set Rating]],1)-2) -> 2 | AP5: =IFERROR(AVERAGEIFS(Data_Discontinuities[[#All],[Jr/Ja]],Data_Discontinuities[[#All],[Hole ID]],"="&Data_Geotech[[#This Row],[Hole ID]],Data_Discontinuities[[#All],[Depth (m)]],">="&Data_Geotech[[#This Row],[From (m)]],Data_Discontinuities[[#All],[Depth (m)]],"<"&Data_Geotech[[#This Row],[To (m)]]),IF(Data_Geotech[[#This Row],[Added fractures (BC, FLT, LC)]]>Data_Geotech[[#This Row],[Fracture per interval]],1/4,IF(Data_Geotech[[#This Row],[Fracture per interval]]=0,4/0.75,"ERROR: should never happen!"))) -> 2.25 | AQ5: =1/1 -> 1 | AR5: =IF(Data_Geotech[[#This Row],[FIRS Code]]="R",IFERROR((IF(Data_Geotech[[#This Row],[RQD (%)]]<10,10,Data_Geotech[[#This Row],[RQD (%)]])/Data_Geotech[[#This Row],[Jn rating]])*Data_Geotech[[#This Row],[Jr/Ja]],""),"") -> 112.5 | AS5: =IF(Data_Geotech[[#This Row],[FIRS Code]]="R",IFERROR((IF(Data_Geotech[[#This Row],[RQD (%)]]<10,10,Data_Geotech[[#This Row],[RQD (%)]])/Data_Geotech[[#This Row],[Jn rating]])*Data_Geotech[[#This Row],[Jr/Ja]]*Data_Geotech[[#This Row],[Jw/SRF]],""),"") -> 112.5 | AU5: =100-Data_Geotech[[#This Row],[RQD (%)]] -> 0 | AV5: =100-Data_Geotech[[#This Row],[TCR (%)]] -> 2.7000624e-13 | AW5: =(Data_Geotech[[#This Row],[Fracture per interval]]+Data_Geotech[[#This Row],[Added fractures (BC, FLT, LC)]])/Data_Geotech[[#This Row],[TCR (m)]] -> 1.3513514 | AX5: R | AY5: =7-MID(Data_Geotech[[#This Row],[Field Intact Rock Strength]],2,1) -> 1 | AZ5: =VLOOKUP(Data_Geotech[[#This Row],[Field Intact Rock Strength]],Table_FieldStrength[],2,FALSE) -> 250 | BA5: =VLOOKUP(Data_Geotech[[#This Row],[Field Intact Rock Strength]],Table_FieldStrength[],3,FALSE) -> 275 | BB5: =VLOOKUP(Data_Geotech[[#This Row],[Field Intact Rock Strength]],Table_FieldStrength[],4,FALSE) -> 300 | BC5: =100-Data_Geotech[[#This Row],[RMR76]] -> 25 | BD5: =LEFT(Data_Geotech[[#This Row],[Weathering/Alteration]],FIND("-",Data_Geotech[[#This Row],[Weathering/Alteration]])-2) -> W1/A1
A6: COG-25-08 | B6: =VLOOKUP(Data_Geotech[[#This Row],[Hole ID]],Data_Log[],2,FALSE) -> CGF-01 | C6: 52.46 | D6: 52.96 | E6: =(Data_Geotech[[#This Row],[To (m)]]-Data_Geotech[[#This Row],[From (m)]])/2+Data_Geotech[[#This Row],[From (m)]] -> 52.71 | F6: =Data_Geotech[[#This Row],[To (m)]]-Data_Geotech[[#This Row],[From (m)]] -> 0.5 | G6: 0.5 | H6: =Data_Geotech[[#This Row],[TCR (m)]]/Data_Geotech[[#This Row],[Run (m)]]*100 -> 100 | I6: 0.52 | J6: 0.52 | K6: 0.52 | L6: =Data_Geotech[[#This Row],[RQD (m)]]/Data_Geotech[[#This Row],[Run Reel (m)]]*100 -> 100 | M6: Boulamarque granodiorite | O6: W1/A1 - Fresh | P6: R6 - Extremely strong | Q6: 2 - Moderate | V6: 1 | W6: =SUMIFS(Discontinuities!$D$4:$D$9664,Discontinuities!$A$4:$A$9664,A6,Discontinuities!$C$4:$C$9664,">="&C6,Discontinuities!$C$4:$C$9664,"<"&D6) -SUMIFS(Discontinuities!$D$4:$D$9664,Discontinuities!$A$4:$A$9664,A6,Discontinuities!$C$4:$C$9664,">="&C6,Discontinuities!$C$4:$C$9664,"<"&D6,Discontinuities!$E$4:$E$9664,"=BC") -SUMIFS(Discontinuities!$D$4:$D$9664,Discontinuities!$A$4:$A$9664,A6,Discontinuities!$C$4:$C$9664,">="&C6,Discontinuities!$C$4:$C$9664,"<"&D6,Discontinuities!$E$4:$E$9664,"=LC") -SUMIFS(Discontinuities!$D$4:$D$9664,Discontinuities!$A$4:$A$9664,A6,Discontinuities!$C$4:$C$9664,">="&C6,Discontinuities!$C$4:$C$9664,"<"&D6,Discontinuities!$E$4:$E$9664,"=FLT") -> 1 | X6: 1 - Massive or few joints | AB6: =IFERROR(ROUND((Data_Geotech[[#This Row],[Fault (m)]]+Data_Geotech[[#This Row],[Broken Core (m)]]+Data_Geotech[[#This Row],[Lost Core (m)]])*30,0),0) -> 0 | AC6: =IF(Data_Geotech[[#This Row],[Added fractures (BC, FLT, LC)]]+Data_Geotech[[#This Row],[Fracture per interval]]=0,99,1/((Data_Geotech[[#This Row],[Fracture per interval]]+Data_Geotech[[#This Row],[Added fractures (BC, FLT, LC)]])/Data_Geotech[[#This Row],[Run (m)]])) -> 0.5 | AD6: {=IFERROR(_xlfn.XLOOKUP(1,(A6=PLT!$A$4:$A$8886)*(Geotech!C6<=PLT!$F$4:$F$8886)*(Geotech!D6>=PLT!$F$4:$F$8886)*("Valid"=PLT!$P$4:$P$8886),PLT!$V$4:$V$8886),"")} | AE6: {=IFERROR(_xlfn.XLOOKUP(1,(A6=PLT!$A$4:$A$8886)*(Geotech!C6<=PLT!$F$4:$F$8886)*(Geotech!D6>=PLT!$F$4:$F$8886)*(PLT!$V$4:$V$8886<>AD6)*("Valid"=PLT!$P$4:$P$7190),PLT!$V$4:$V$8886),"")} | AF6: {=IFERROR(_xlfn.XLOOKUP(1,(A6=PLT!$A$4:$A$8886)*(Geotech!C6<=PLT!$F$4:$F$8886)*(Geotech!D6>=PLT!$F$4:$F$8886)*(PLT!$V$4:$V$8886<>AD6)*(PLT!$V$4:$V$8886<>AE6)*("Valid"=PLT!$P$4:$P$7190),PLT!$V$4:$V$8886),"")} | AG6: =IFERROR(IF(AVERAGE(AD6:AF6)>References!$BO$23,References!$BP$23, IF(AVERAGE(AD6:AF6)>References!$BO$22,References!$BP$22, IF(AVERAGE(AD6:AF6)>References!$BO$21,References!$BP$21, IF(AVERAGE(AD6:AF6)>References!$BO$20,References!$BP$20, IF(AVERAGE(AD6:AF6)>References!$BO$19,References!$BP$19, IF(AVERAGE(AD6:AF6)>References!$BO$18,References!$BP$18, 0)))))),"") | AH6: =IF(Data_Geotech[[#This Row],[Is50]]="",VLOOKUP(Data_Geotech[[#This Row],[Field Intact Rock Strength]],Table_RMR76_Strength[],2,FALSE),Data_Geotech[[#This Row],[Is50]]) -> 15 | AI6: =IF(Data_Geotech[[#This Row],[RQD (%)]]<=25,3,IF(Data_Geotech[[#This Row],[RQD (%)]]<=50,8,IF(Data_Geotech[[#This Row],[RQD (%)]]<=75,13,IF(Data_Geotech[[#This Row],[RQD (%)]]<=90,17,20)))) -> 20 | AJ6: =IF(Data_Geotech[[#This Row],[Joint spacing (m)]]<=0.05,5,IF(Data_Geotech[[#This Row],[Joint spacing (m)]]<=0.3,10,IF(Data_Geotech[[#This Row],[Joint spacing (m)]]<=1,20,IF(Data_Geotech[[#This Row],[Joint spacing (m)]]<=3,25,30)))) -> 20 | AK6: =IFERROR(AVERAGEIFS(Data_Discontinuities[[#All],[JCR]],Data_Discontinuities[[#All],[Hole ID]],"="&Data_Geotech[[#This Row],[Hole ID]],Data_Discontinuities[[#All],[Depth (m)]],">="&Data_Geotech[[#This Row],[From (m)]],Data_Discontinuities[[#All],[Depth (m)]],"<"&Data_Geotech[[#This Row],[To (m)]]),IF(Data_Geotech[[#This Row],[Added fractures (BC, FLT, LC)]]=0,IF(Data_Geotech[[#This Row],[Fracture per interval]]=0,25,6),6)) -> 6 | AL6: 10 | AM6: =IF(Data_Geotech[[#This Row],[FIRS Code]]="R",IFERROR(SUM(Data_Geotech[[#This Row],[RMR76 - Strength rating]:[RMR76 - Ground water rating]]),""),"") -> 71 | AN6: =IF(Data_Geotech[[#This Row],[FIRS Code]]="R",(2*Data_Geotech[[#This Row],[RMR76 - Joint condition rating]])+(IF(Data_Geotech[[#This Row],[RQD (%)]]>80,80/2,Data_Geotech[[#This Row],[RQD (%)]]/2)),"") -> 52 | AO6: =LEFT(Data_Geotech[[#This Row],[Joint Set Rating]],FIND("-",Data_Geotech[[#This Row],[Joint Set Rating]],1)-2) -> 1 | AP6: =IFERROR(AVERAGEIFS(Data_Discontinuities[[#All],[Jr/Ja]],Data_Discontinuities[[#All],[Hole ID]],"="&Data_Geotech[[#This Row],[Hole ID]],Data_Discontinuities[[#All],[Depth (m)]],">="&Data_Geotech[[#This Row],[From (m)]],Data_Discontinuities[[#All],[Depth (m)]],"<"&Data_Geotech[[#This Row],[To (m)]]),IF(Data_Geotech[[#This Row],[Added fractures (BC, FLT, LC)]]>Data_Geotech[[#This Row],[Fracture per interval]],1/4,IF(Data_Geotech[[#This Row],[Fracture per interval]]=0,4/0.75,"ERROR: should never happen!"))) -> 0.25 | AQ6: =1/1 -> 1 | AR6: =IF(Data_Geotech[[#This Row],[FIRS Code]]="R",IFERROR((IF(Data_Geotech[[#This Row],[RQD (%)]]<10,10,Data_Geotech[[#This Row],[RQD (%)]])/Data_Geotech[[#This Row],[Jn rating]])*Data_Geotech[[#This Row],[Jr/Ja]],""),"") -> 25 | AS6: =IF(Data_Geotech[[#This Row],[FIRS Code]]="R",IFERROR((IF(Data_Geotech[[#This Row],[RQD (%)]]<10,10,Data_Geotech[[#This Row],[RQD (%)]])/Data_Geotech[[#This Row],[Jn rating]])*Data_Geotech[[#This Row],[Jr/Ja]]*Data_Geotech[[#This Row],[Jw/SRF]],""),"") -> 25 | AU6: =100-Data_Geotech[[#This Row],[RQD (%)]] -> 0 | AV6: =100-Data_Geotech[[#This Row],[TCR (%)]] -> 0 | AW6: =(Data_Geotech[[#This Row],[Fracture per interval]]+Data_Geotech[[#This Row],[Added fractures (BC, FLT, LC)]])/Data_Geotech[[#This Row],[TCR (m)]] -> 2 | AX6: R | AY6: =7-MID(Data_Geotech[[#This Row],[Field Intact Rock Strength]],2,1) -> 1 | AZ6: =VLOOKUP(Data_Geotech[[#This Row],[Field Intact Rock Strength]],Table_FieldStrength[],2,FALSE) -> 250 | BA6: =VLOOKUP(Data_Geotech[[#This Row],[Field Intact Rock Strength]],Table_FieldStrength[],3,FALSE) -> 275 | BB6: =VLOOKUP(Data_Geotech[[#This Row],[Field Intact Rock Strength]],Table_FieldStrength[],4,FALSE) -> 300 | BC6: =100-Data_Geotech[[#This Row],[RMR76]] -> 29 | BD6: =LEFT(Data_Geotech[[#This Row],[Weathering/Alteration]],FIND("-",Data_Geotech[[#This Row],[Weathering/Alteration]])-2) -> W1/A1
A7: COG-25-08 | B7: =VLOOKUP(Data_Geotech[[#This Row],[Hole ID]],Data_Log[],2,FALSE) -> CGF-01 | C7: 52.96 | D7: 54 | E7: =(Data_Geotech[[#This Row],[To (m)]]-Data_Geotech[[#This Row],[From (m)]])/2+Data_Geotech[[#This Row],[From (m)]] -> 53.48 | F7: =Data_Geotech[[#This Row],[To (m)]]-Data_Geotech[[#This Row],[From (m)]] -> 1.04 | G7: 1.04 | H7: =Data_Geotech[[#This Row],[TCR (m)]]/Data_Geotech[[#This Row],[Run (m)]]*100 -> 100 | I7: 1.07 | J7: 1.07 | K7: =1.07-0.06 -> 1.01 | L7: =Data_Geotech[[#This Row],[RQD (m)]]/Data_Geotech[[#This Row],[Run Reel (m)]]*100 -> 94.392523 | M7: Diorite | O7: W2/A2 - Slightly Weathered or Altered | P7: R3 - Moderately strong | Q7: 2 - Moderate | V7: 3 | W7: =SUMIFS(Discontinuities!$D$4:$D$9664,Discontinuities!$A$4:$A$9664,A7,Discontinuities!$C$4:$C$9664,">="&C7,Discontinuities!$C$4:$C$9664,"<"&D7) -SUMIFS(Discontinuities!$D$4:$D$9664,Discontinuities!$A$4:$A$9664,A7,Discontinuities!$C$4:$C$9664,">="&C7,Discontinuities!$C$4:$C$9664,"<"&D7,Discontinuities!$E$4:$E$9664,"=BC") -SUMIFS(Discontinuities!$D$4:$D$9664,Discontinuities!$A$4:$A$9664,A7,Discontinuities!$C$4:$C$9664,">="&C7,Discontinuities!$C$4:$C$9664,"<"&D7,Discontinuities!$E$4:$E$9664,"=LC") -SUMIFS(Discontinuities!$D$4:$D$9664,Discontinuities!$A$4:$A$9664,A7,Discontinuities!$C$4:$C$9664,">="&C7,Discontinuities!$C$4:$C$9664,"<"&D7,Discontinuities!$E$4:$E$9664,"=FLT") -> 3 | X7: 3 - One joint set plus random joint (s) | AB7: =IFERROR(ROUND((Data_Geotech[[#This Row],[Fault (m)]]+Data_Geotech[[#This Row],[Broken Core (m)]]+Data_Geotech[[#This Row],[Lost Core (m)]])*30,0),0) -> 0 | AC7: =IF(Data_Geotech[[#This Row],[Added fractures (BC, FLT, LC)]]+Data_Geotech[[#This Row],[Fracture per interval]]=0,99,1/((Data_Geotech[[#This Row],[Fracture per interval]]+Data_Geotech[[#This Row],[Added fractures (BC, FLT, LC)]])/Data_Geotech[[#This Row],[Run (m)]])) -> 0.34666667 | AD7: {=IFERROR(_xlfn.XLOOKUP(1,(A7=PLT!$A$4:$A$8886)*(Geotech!C7<=PLT!$F$4:$F$8886)*(Geotech!D7>=PLT!$F$4:$F$8886)*("Valid"=PLT!$P$4:$P$8886),PLT!$V$4:$V$8886),"")} -> 0 | AE7: {=IFERROR(_xlfn.XLOOKUP(1,(A7=PLT!$A$4:$A$8886)*(Geotech!C7<=PLT!$F$4:$F$8886)*(Geotech!D7>=PLT!$F$4:$F$8886)*(PLT!$V$4:$V$8886<>AD7)*("Valid"=PLT!$P$4:$P$7190),PLT!$V$4:$V$8886),"")} | AF7: {=IFERROR(_xlfn.XLOOKUP(1,(A7=PLT!$A$4:$A$8886)*(Geotech!C7<=PLT!$F$4:$F$8886)*(Geotech!D7>=PLT!$F$4:$F$8886)*(PLT!$V$4:$V$8886<>AD7)*(PLT!$V$4:$V$8886<>AE7)*("Valid"=PLT!$P$4:$P$7190),PLT!$V$4:$V$8886),"")} | AG7: =IFERROR(IF(AVERAGE(AD7:AF7)>References!$BO$23,References!$BP$23, IF(AVERAGE(AD7:AF7)>References!$BO$22,References!$BP$22, IF(AVERAGE(AD7:AF7)>References!$BO$21,References!$BP$21, IF(AVERAGE(AD7:AF7)>References!$BO$20,References!$BP$20, IF(AVERAGE(AD7:AF7)>References!$BO$19,References!$BP$19, IF(AVERAGE(AD7:AF7)>References!$BO$18,References!$BP$18, 0)))))),"") -> 0 | AH7: =IF(Data_Geotech[[#This Row],[Is50]]="",VLOOKUP(Data_Geotech[[#This Row],[Field Intact Rock Strength]],Table_RMR76_Strength[],2,FALSE),Data_Geotech[[#This Row],[Is50]]) -> 0 | AI7: =IF(Data_Geotech[[#This Row],[RQD (%)]]<=25,3,IF(Data_Geotech[[#This Row],[RQD (%)]]<=50,8,IF(Data_Geotech[[#This Row],[RQD (%)]]<=75,13,IF(Data_Geotech[[#This Row],[RQD (%)]]<=90,17,20)))) -> 20 | AJ7: =IF(Data_Geotech[[#This Row],[Joint spacing (m)]]<=0.05,5,IF(Data_Geotech[[#This Row],[Joint spacing (m)]]<=0.3,10,IF(Data_Geotech[[#This Row],[Joint spacing (m)]]<=1,20,IF(Data_Geotech[[#This Row],[Joint spacing (m)]]<=3,25,30)))) -> 20 | AK7: =IFERROR(AVERAGEIFS(Data_Discontinuities[[#All],[JCR]],Data_Discontinuities[[#All],[Hole ID]],"="&Data_Geotech[[#This Row],[Hole ID]],Data_Discontinuities[[#All],[Depth (m)]],">="&Data_Geotech[[#This Row],[From (m)]],Data_Discontinuities[[#All],[Depth (m)]],"<"&Data_Geotech[[#This Row],[To (m)]]),IF(Data_Geotech[[#This Row],[Added fractures (BC, FLT, LC)]]=0,IF(Data_Geotech[[#This Row],[Fracture per interval]]=0,25,6),6)) -> 14.666667 | AL7: 10 | AM7: =IF(Data_Geotech[[#This Row],[FIRS Code]]="R",IFERROR(SUM(Data_Geotech[[#This Row],[RMR76 - Strength rating]:[RMR76 - Ground water rating]]),""),"") -> 64.666667 | AN7: =IF(Data_Geotech[[#This Row],[FIRS Code]]="R",(2*Data_Geotech[[#This Row],[RMR76 - Joint condition rating]])+(IF(Data_Geotech[[#This Row],[RQD (%)]]>80,80/2,Data_Geotech[[#This Row],[RQD (%)]]/2)),"") -> 69.333333 | AO7: =LEFT(Data_Geotech[[#This Row],[Joint Set Rating]],FIND("-",Data_Geotech[[#This Row],[Joint Set Rating]],1)-2) -> 3 | AP7: =IFERROR(AVERAGEIFS(Data_Discontinuities[[#All],[Jr/Ja]],Data_Discontinuities[[#All],[Hole ID]],"="&Data_Geotech[[#This Row],[Hole ID]],Data_Discontinuities[[#All],[Depth (m)]],">="&Data_Geotech[[#This Row],[From (m)]],Data_Discontinuities[[#All],[Depth (m)]],"<"&Data_Geotech[[#This Row],[To (m)]]),IF(Data_Geotech[[#This Row],[Added fractures (BC, FLT, LC)]]>Data_Geotech[[#This Row],[Fracture per interval]],1/4,IF(Data_Geotech[[#This Row],[Fracture per interval]]=0,4/0.75,"ERROR: should never happen!"))) -> 0.54166667 | AQ7: =1/1 -> 1 | AR7: =IF(Data_Geotech[[#This Row],[FIRS Code]]="R",IFERROR((IF(Data_Geotech[[#This Row],[RQD (%)]]<10,10,Data_Geotech[[#This Row],[RQD (%)]])/Data_Geotech[[#This Row],[Jn rating]])*Data_Geotech[[#This Row],[Jr/Ja]],""),"") -> 17.043094 | AS7: =IF(Data_Geotech[[#This Row],[FIRS Code]]="R",IFERROR((IF(Data_Geotech[[#This Row],[RQD (%)]]<10,10,Data_Geotech[[#This Row],[RQD (%)]])/Data_Geotech[[#This Row],[Jn rating]])*Data_Geotech[[#This Row],[Jr/Ja]]*Data_Geotech[[#This Row],[Jw/SRF]],""),"") -> 17.043094 | AU7: =100-Data_Geotech[[#This Row],[RQD (%)]] -> 5.6074766 | AV7: =100-Data_Geotech[[#This Row],[TCR (%)]] -> 0 | AW7: =(Data_Geotech[[#This Row],[Fracture per interval]]+Data_Geotech[[#This Row],[Added fractures (BC, FLT, LC)]])/Data_Geotech[[#This Row],[TCR (m)]] -> 2.8846154 | AX7: R | AY7: =7-MID(Data_Geotech[[#This Row],[Field Intact Rock Strength]],2,1) -> 4 | AZ7: =VLOOKUP(Data_Geotech[[#This Row],[Field Intact Rock Strength]],Table_FieldStrength[],2,FALSE) -> 25 | BA7: =VLOOKUP(Data_Geotech[[#This Row],[Field Intact Rock Strength]],Table_FieldStrength[],3,FALSE) -> 37.5 | BB7: =VLOOKUP(Data_Geotech[[#This Row],[Field Intact Rock Strength]],Table_FieldStrength[],4,FALSE) -> 50 | BC7: =100-Data_Geotech[[#This Row],[RMR76]] -> 35.333333 | BD7: =LEFT(Data_Geotech[[#This Row],[Weathering/Alteration]],FIND("-",Data_Geotech[[#This Row],[Weathering/Alteration]])-2) -> W2/A2
A8: COG-25-08 | B8: =VLOOKUP(Data_Geotech[[#This Row],[Hole ID]],Data_Log[],2,FALSE) -> CGF-01 | C8: 54 | D8: 54.9 | E8: =(Data_Geotech[[#This Row],[To (m)]]-Data_Geotech[[#This Row],[From (m)]])/2+Data_Geotech[[#This Row],[From (m)]] -> 54.45 | F8: =Data_Geotech[[#This Row],[To (m)]]-Data_Geotech[[#This Row],[From (m)]] -> 0.9 | G8: 0.9 | H8: =Data_Geotech[[#This Row],[TCR (m)]]/Data_Geotech[[#This Row],[Run (m)]]*100 -> 100 | I8: 0.9 | J8: 0.9 | K8: 0.9 | L8: =Data_Geotech[[#This Row],[RQD (m)]]/Data_Geotech[[#This Row],[Run Reel (m)]]*100 -> 100 | M8: Diorite | O8: W2/A2 - Slightly Weathered or Altered | P8: R5 - Very strong | Q8: 3 - Intense | V8: 3 | W8: =SUMIFS(Discontinuities!$D$4:$D$9664,Discontinuities!$A$4:$A$9664,A8,Discontinuities!$C$4:$C$9664,">="&C8,Discontinuities!$C$4:$C$9664,"<"&D8) -SUMIFS(Discontinuities!$D$4:$D$9664,Discontinuities!$A$4:$A$9664,A8,Discontinuities!$C$4:$C$9664,">="&C8,Discontinuities!$C$4:$C$9664,"<"&D8,Discontinuities!$E$4:$E$9664,"=BC") -SUMIFS(Discontinuities!$D$4:$D$9664,Discontinuities!$A$4:$A$9664,A8,Discontinuities!$C$4:$C$9664,">="&C8,Discontinuities!$C$4:$C$9664,"<"&D8,Discontinuities!$E$4:$E$9664,"=LC") -SUMIFS(Discontinuities!$D$4:$D$9664,Discontinuities!$A$4:$A$9664,A8,Discontinuities!$C$4:$C$9664,">="&C8,Discontinuities!$C$4:$C$9664,"<"&D8,Discontinuities!$E$4:$E$9664,"=FLT") -> 3 | X8: 2 - One joint set | AB8: =IFERROR(ROUND((Data_Geotech[[#This Row],[Fault (m)]]+Data_Geotech[[#This Row],[Broken Core (m)]]+Data_Geotech[[#This Row],[Lost Core (m)]])*30,0),0) -> 0 | AC8: =IF(Data_Geotech[[#This Row],[Added fractures (BC, FLT, LC)]]+Data_Geotech[[#This Row],[Fracture per interval]]=0,99,1/((Data_Geotech[[#This Row],[Fracture per interval]]+Data_Geotech[[#This Row],[Added fractures (BC, FLT, LC)]])/Data_Geotech[[#This Row],[Run (m)]])) -> 0.3 | AD8: {=IFERROR(_xlfn.XLOOKUP(1,(A8=PLT!$A$4:$A$8886)*(Geotech!C8<=PLT!$F$4:$F$8886)*(Geotech!D8>=PLT!$F$4:$F$8886)*("Valid"=PLT!$P$4:$P$8886),PLT!$V$4:$V$8886),"")} -> 0 | AE8: {=IFERROR(_xlfn.XLOOKUP(1,(A8=PLT!$A$4:$A$8886)*(Geotech!C8<=PLT!$F$4:$F$8886)*(Geotech!D8>=PLT!$F$4:$F$8886)*(PLT!$V$4:$V$8886<>AD8)*("Valid"=PLT!$P$4:$P$7190),PLT!$V$4:$V$8886),"")} | AF8: {=IFERROR(_xlfn.XLOOKUP(1,(A8=PLT!$A$4:$A$8886)*(Geotech!C8<=PLT!$F$4:$F$8886)*(Geotech!D8>=PLT!$F$4:$F$8886)*(PLT!$V$4:$V$8886<>AD8)*(PLT!$V$4:$V$8886<>AE8)*("Valid"=PLT!$P$4:$P$7190),PLT!$V$4:$V$8886),"")} | AG8: =IFERROR(IF(AVERAGE(AD8:AF8)>References!$BO$23,References!$BP$23, IF(AVERAGE(AD8:AF8)>References!$BO$22,References!$BP$22, IF(AVERAGE(AD8:AF8)>References!$BO$21,References!$BP$21, IF(AVERAGE(AD8:AF8)>References!$BO$20,References!$BP$20, IF(AVERAGE(AD8:AF8)>References!$BO$19,References!$BP$19, IF(AVERAGE(AD8:AF8)>References!$BO$18,References!$BP$18, 0)))))),"") -> 0 | AH8: =IF(Data_Geotech[[#This Row],[Is50]]="",VLOOKUP(Data_Geotech[[#This Row],[Field Intact Rock Strength]],Table_RMR76_Strength[],2,FALSE),Data_Geotech[[#This Row],[Is50]]) -> 0 | AI8: =IF(Data_Geotech[[#This Row],[RQD (%)]]<=25,3,IF(Data_Geotech[[#This Row],[RQD (%)]]<=50,8,IF(Data_Geotech[[#This Row],[RQD (%)]]<=75,13,IF(Data_Geotech[[#This Row],[RQD (%)]]<=90,17,20)))) -> 20 | AJ8: =IF(Data_Geotech[[#This Row],[Joint spacing (m)]]<=0.05,5,IF(Data_Geotech[[#This Row],[Joint spacing (m)]]<=0.3,10,IF(Data_Geotech[[#This Row],[Joint spacing (m)]]<=1,20,IF(Data_Geotech[[#This Row],[Joint spacing (m)]]<=3,25,30)))) -> 10 | AK8: =IFERROR(AVERAGEIFS(Data_Discontinuities[[#All],[JCR]],Data_Discontinuities[[#All],[Hole ID]],"="&Data_Geotech[[#This Row],[Hole ID]],Data_Discontinuities[[#All],[Depth (m)]],">="&Data_Geotech[[#This Row],[From (m)]],Data_Discontinuities[[#All],[Depth (m)]],"<"&Data_Geotech[[#This Row],[To (m)]]),IF(Data_Geotech[[#This Row],[Added fractures (BC, FLT, LC)]]=0,IF(Data_Geotech[[#This Row],[Fracture per interval]]=0,25,6),6)) -> 20 | AL8: 10 | AM8: =IF(Data_Geotech[[#This Row],[FIRS Code]]="R",IFERROR(SUM(Data_Geotech[[#This Row],[RMR76 - Strength rating]:[RMR76 - Ground water rating]]),""),"") -> 60 | AN8: =IF(Data_Geotech[[#This Row],[FIRS Code]]="R",(2*Data_Geotech[[#This Row],[RMR76 - Joint condition rating]])+(IF(Data_Geotech[[#This Row],[RQD (%)]]>80,80/2,Data_Geotech[[#This Row],[RQD (%)]]/2)),"") -> 80 | AO8: =_xlfn.NUMBERVALUE(LEFT(Data_Geotech[[#This Row],[Joint Set Rating]],FIND("-",Data_Geotech[[#This Row],[Joint Set Rating]],1)-2)) -> 2 | AP8: =IFERROR(AVERAGEIFS(Data_Discontinuities[[#All],[Jr/Ja]],Data_Discontinuities[[#All],[Hole ID]],"="&Data_Geotech[[#This Row],[Hole ID]],Data_Discontinuities[[#All],[Depth (m)]],">="&Data_Geotech[[#This Row],[From (m)]],Data_Discontinuities[[#All],[Depth (m)]],"<"&Data_Geotech[[#This Row],[To (m)]]),IF(Data_Geotech[[#This Row],[Added fractures (BC, FLT, LC)]]>Data_Geotech[[#This Row],[Fracture per interval]],1/4,IF(Data_Geotech[[#This Row],[Fracture per interval]]=0,4/0.75,"ERROR: should never happen!"))) -> 0.75 | AQ8: =1/1 -> 1 | AR8: =IF(Data_Geotech[[#This Row],[FIRS Code]]="R",IFERROR((IF(Data_Geotech[[#This Row],[RQD (%)]]<10,10,Data_Geotech[[#This Row],[RQD (%)]])/Data_Geotech[[#This Row],[Jn rating]])*Data_Geotech[[#This Row],[Jr/Ja]],""),"") -> 37.5 | AS8: =IF(Data_Geotech[[#This Row],[FIRS Code]]="R",IFERROR((IF(Data_Geotech[[#This Row],[RQD (%)]]<10,10,Data_Geotech[[#This Row],[RQD (%)]])/Data_Geotech[[#This Row],[Jn rating]])*Data_Geotech[[#This Row],[Jr/Ja]]*Data_Geotech[[#This Row],[Jw/SRF]],""),"") -> 37.5 | AU8: =100-Data_Geotech[[#This Row],[RQD (%)]] -> 0 | AV8: =100-Data_Geotech[[#This Row],[TCR (%)]] -> -1.563194e-13 | AW8: =(Data_Geotech[[#This Row],[Fracture per interval]]+Data_Geotech[[#This Row],[Added fractures (BC, FLT, LC)]])/Data_Geotech[[#This Row],[TCR (m)]] -> 3.3333333 | AX8: R | AY8: =7-MID(Data_Geotech[[#This Row],[Field Intact Rock Strength]],2,1) -> 2 | AZ8: =VLOOKUP(Data_Geotech[[#This Row],[Field Intact Rock Strength]],Table_FieldStrength[],2,FALSE) -> 100 | BA8: =VLOOKUP(Data_Geotech[[#This Row],[Field Intact Rock Strength]],Table_FieldStrength[],3,FALSE) -> 175 | BB8: =VLOOKUP(Data_Geotech[[#This Row],[Field Intact Rock Strength]],Table_FieldStrength[],4,FALSE) -> 250 | BC8: =100-Data_Geotech[[#This Row],[RMR76]] -> 40 | BD8: =LEFT(Data_Geotech[[#This Row],[Weathering/Alteration]],FIND("-",Data_Geotech[[#This Row],[Weathering/Alteration]])-2) -> W2/A2
A9: COG-25-08 | B9: =VLOOKUP(Data_Geotech[[#This Row],[Hole ID]],Data_Log[],2,FALSE) -> CGF-01 | C9: 54.9 | D9: 55.38 | E9: =(Data_Geotech[[#This Row],[To (m)]]-Data_Geotech[[#This Row],[From (m)]])/2+Data_Geotech[[#This Row],[From (m)]] -> 55.14 | F9: =Data_Geotech[[#This Row],[To (m)]]-Data_Geotech[[#This Row],[From (m)]] -> 0.48 | G9: 0.48 | H9: =Data_Geotech[[#This Row],[TCR (m)]]/Data_Geotech[[#This Row],[Run (m)]]*100 -> 100 | I9: 0.47 | J9: 0.47 | K9: 0.47 | L9: =Data_Geotech[[#This Row],[RQD (m)]]/Data_Geotech[[#This Row],[Run Reel (m)]]*100 -> 100 | M9: Boulamarque granodiorite | O9: W1/A1 - Fresh | P9: R6 - Extremely strong | Q9: 1 - Weak | V9: 0 | W9: =SUMIFS(Discontinuities!$D$4:$D$9664,Discontinuities!$A$4:$A$9664,A9,Discontinuities!$C$4:$C$9664,">="&C9,Discontinuities!$C$4:$C$9664,"<"&D9) -SUMIFS(Discontinuities!$D$4:$D$9664,Discontinuities!$A$4:$A$9664,A9,Discontinuities!$C$4:$C$9664,">="&C9,Discontinuities!$C$4:$C$9664,"<"&D9,Discontinuities!$E$4:$E$9664,"=BC") -SUMIFS(Discontinuities!$D$4:$D$9664,Discontinuities!$A$4:$A$9664,A9,Discontinuities!$C$4:$C$9664,">="&C9,Discontinuities!$C$4:$C$9664,"<"&D9,Discontinuities!$E$4:$E$9664,"=LC") -SUMIFS(Discontinuities!$D$4:$D$9664,Discontinuities!$A$4:$A$9664,A9,Discontinuities!$C$4:$C$9664,">="&C9,Discontinuities!$C$4:$C$9664,"<"&D9,Discontinuities!$E$4:$E$9664,"=FLT") -> 0 | X9: 0.5 - Massive | AB9: =IFERROR(ROUND((Data_Geotech[[#This Row],[Fault (m)]]+Data_Geotech[[#This Row],[Broken Core (m)]]+Data_Geotech[[#This Row],[Lost Core (m)]])*30,0),0) -> 0 | AC9: =IF(Data_Geotech[[#This Row],[Added fractures (BC, FLT, LC)]]+Data_Geotech[[#This Row],[Fracture per interval]]=0,99,1/((Data_Geotech[[#This Row],[Fracture per interval]]+Data_Geotech[[#This Row],[Added fractures (BC, FLT, LC)]])/Data_Geotech[[#This Row],[Run (m)]])) -> 99 | AD9: {=IFERROR(_xlfn.XLOOKUP(1,(A9=PLT!$A$4:$A$8886)*(Geotech!C9<=PLT!$F$4:$F$8886)*(Geotech!D9>=PLT!$F$4:$F$8886)*("Valid"=PLT!$P$4:$P$8886),PLT!$V$4:$V$8886),"")} -> 0 | AE9: {=IFERROR(_xlfn.XLOOKUP(1,(A9=PLT!$A$4:$A$8886)*(Geotech!C9<=PLT!$F$4:$F$8886)*(Geotech!D9>=PLT!$F$4:$F$8886)*(PLT!$V$4:$V$8886<>AD9)*("Valid"=PLT!$P$4:$P$7190),PLT!$V$4:$V$8886),"")} | AF9: {=IFERROR(_xlfn.XLOOKUP(1,(A9=PLT!$A$4:$A$8886)*(Geotech!C9<=PLT!$F$4:$F$8886)*(Geotech!D9>=PLT!$F$4:$F$8886)*(PLT!$V$4:$V$8886<>AD9)*(PLT!$V$4:$V$8886<>AE9)*("Valid"=PLT!$P$4:$P$7190),PLT!$V$4:$V$8886),"")} | AG9: =IFERROR(IF(AVERAGE(AD9:AF9)>References!$BO$23,References!$BP$23, IF(AVERAGE(AD9:AF9)>References!$BO$22,References!$BP$22, IF(AVERAGE(AD9:AF9)>References!$BO$21,References!$BP$21, IF(AVERAGE(AD9:AF9)>References!$BO$20,References!$BP$20, IF(AVERAGE(AD9:AF9)>References!$BO$19,References!$BP$19, IF(AVERAGE(AD9:AF9)>References!$BO$18,References!$BP$18, 0)))))),"") -> 0 | AH9: =IF(Data_Geotech[[#This Row],[Is50]]="",VLOOKUP(Data_Geotech[[#This Row],[Field Intact Rock Strength]],Table_RMR76_Strength[],2,FALSE),Data_Geotech[[#This Row],[Is50]]) -> 0 | AI9: =IF(Data_Geotech[[#This Row],[RQD (%)]]<=25,3,IF(Data_Geotech[[#This Row],[RQD (%)]]<=50,8,IF(Data_Geotech[[#This Row],[RQD (%)]]<=75,13,IF(Data_Geotech[[#This Row],[RQD (%)]]<=90,17,20)))) -> 20 | AJ9: =IF(Data_Geotech[[#This Row],[Joint spacing (m)]]<=0.05,5,IF(Data_Geotech[[#This Row],[Joint spacing (m)]]<=0.3,10,IF(Data_Geotech[[#This Row],[Joint spacing (m)]]<=1,20,IF(Data_Geotech[[#This Row],[Joint spacing (m)]]<=3,25,30)))) -> 30 | AK9: =IFERROR(AVERAGEIFS(Data_Discontinuities[[#All],[JCR]],Data_Discontinuities[[#All],[Hole ID]],"="&Data_Geotech[[#This Row],[Hole ID]],Data_Discontinuities[[#All],[Depth (m)]],">="&Data_Geotech[[#This Row],[From (m)]],Data_Discontinuities[[#All],[Depth (m)]],"<"&Data_Geotech[[#This Row],[To (m)]]),IF(Data_Geotech[[#This Row],[Added fractures (BC, FLT, LC)]]=0,IF(Data_Geotech[[#This Row],[Fracture per interval]]=0,25,6),6)) -> 25 | AL9: 10 | AM9: =IF(Data_Geotech[[#This Row],[FIRS Code]]="R",IFERROR(SUM(Data_Geotech[[#This Row],[RMR76 - Strength rating]:[RMR76 - Ground water rating]]),""),"") -> 85 | AN9: =IF(Data_Geotech[[#This Row],[FIRS Code]]="R",(2*Data_Geotech[[#This Row],[RMR76 - Joint condition rating]])+(IF(Data_Geotech[[#This Row],[RQD (%)]]>80,80/2,Data_Geotech[[#This Row],[RQD (%)]]/2)),"") -> 90 | AO9: =LEFT(Data_Geotech[[#This Row],[Joint Set Rating]],FIND("-",Data_Geotech[[#This Row],[Joint Set Rating]],1)-2) -> 0.5 | AP9: =IFERROR(AVERAGEIFS(Data_Discontinuities[[#All],[Jr/Ja]],Data_Discontinuities[[#All],[Hole ID]],"="&Data_Geotech[[#This Row],[Hole ID]],Data_Discontinuities[[#All],[Depth (m)]],">="&Data_Geotech[[#This Row],[From (m)]],Data_Discontinuities[[#All],[Depth (m)]],"<"&Data_Geotech[[#This Row],[To (m)]]),IF(Data_Geotech[[#This Row],[Added fractures (BC, FLT, LC)]]>Data_Geotech[[#This Row],[Fracture per interval]],1/4,IF(Data_Geotech[[#This Row],[Fracture per interval]]=0,4/0.75,"ERROR: should never happen!"))) -> 5.3333333 | AQ9: =1/1 -> 1 | AR9: =IF(Data_Geotech[[#This Row],[FIRS Code]]="R",IFERROR((IF(Data_Geotech[[#This Row],[RQD (%)]]<10,10,Data_Geotech[[#This Row],[RQD (%)]])/Data_Geotech[[#This Row],[Jn rating]])*Data_Geotech[[#This Row],[Jr/Ja]],""),"") | AS9: =IF(Data_Geotech[[#This Row],[FIRS Code]]="R",IFERROR((IF(Data_Geotech[[#This Row],[RQD (%)]]<10,10,Data_Geotech[[#This Row],[RQD (%)]])/Data_Geotech[[#This Row],[Jn rating]])*Data_Geotech[[#This Row],[Jr/Ja]]*Data_Geotech[[#This Row],[Jw/SRF]],""),"") | AU9: =100-Data_Geotech[[#This Row],[RQD (%)]] -> 0 | AV9: =100-Data_Geotech[[#This Row],[TCR (%)]] -> 8.3844043e-13 | AW9: =(Data_Geotech[[#This Row],[Fracture per interval]]+Data_Geotech[[#This Row],[Added fractures (BC, FLT, LC)]])/Data_Geotech[[#This Row],[TCR (m)]] -> 0 | AX9: R | AY9: =7-MID(Data_Geotech[[#This Row],[Field Intact Rock Strength]],2,1) -> 1 | AZ9: =VLOOKUP(Data_Geotech[[#This Row],[Field Intact Rock Strength]],Table_FieldStrength[],2,FALSE) -> 250 | BA9: =VLOOKUP(Data_Geotech[[#This Row],[Field Intact Rock Strength]],Table_FieldStrength[],3,FALSE) -> 275 | BB9: =VLOOKUP(Data_Geotech[[#This Row],[Field Intact Rock Strength]],Table_FieldStrength[],4,FALSE) -> 300 | BC9: =100-Data_Geotech[[#This Row],[RMR76]] -> 15 | BD9: =LEFT(Data_Geotech[[#This Row],[Weathering/Alteration]],FIND("-",Data_Geotech[[#This Row],[Weathering/Alteration]])-2) -> W1/A1
A10: COG-25-08 | B10: =VLOOKUP(Data_Geotech[[#This Row],[Hole ID]],Data_Log[],2,FALSE) -> CGF-01 | C10: 55.38 | D10: 56.93 | E10: =(Data_Geotech[[#This Row],[To (m)]]-Data_Geotech[[#This Row],[From (m)]])/2+Data_Geotech[[#This Row],[From (m)]] -> 56.155 | F10: =Data_Geotech[[#This Row],[To (m)]]-Data_Geotech[[#This Row],[From (m)]] -> 1.55 | G10: 1.55 | H10: =Data_Geotech[[#This Row],[TCR (m)]]/Data_Geotech[[#This Row],[Run (m)]]*100 -> 100 | I10: 1.54 | J10: 1.54 | K10: 1.54 | L10: =Data_Geotech[[#This Row],[RQD (m)]]/Data_Geotech[[#This Row],[Run Reel (m)]]*100 -> 100 | M10: Diorite | O10: W1/A1 - Fresh | P10: R6 - Extremely strong | Q10: 2 - Moderate | V10: 0 | W10: =SUMIFS(Discontinuities!$D$4:$D$9664,Discontinuities!$A$4:$A$9664,A10,Discontinuities!$C$4:$C$9664,">="&C10,Discontinuities!$C$4:$C$9664,"<"&D10) -SUMIFS(Discontinuities!$D$4:$D$9664,Discontinuities!$A$4:$A$9664,A10,Discontinuities!$C$4:$C$9664,">="&C10,Discontinuities!$C$4:$C$9664,"<"&D10,Discontinuities!$E$4:$E$9664,"=BC") -SUMIFS(Discontinuities!$D$4:$D$9664,Discontinuities!$A$4:$A$9664,A10,Discontinuities!$C$4:$C$9664,">="&C10,Discontinuities!$C$4:$C$9664,"<"&D10,Discontinuities!$E$4:$E$9664,"=LC") -SUMIFS(Discontinuities!$D$4:$D$9664,Discontinuities!$A$4:$A$9664,A10,Discontinuities!$C$4:$C$9664,">="&C10,Discontinuities!$C$4:$C$9664,"<"&D10,Discontinuities!$E$4:$E$9664,"=FLT") -> 0 | X10: 0.5 - Massive | AB10: =IFERROR(ROUND((Data_Geotech[[#This Row],[Fault (m)]]+Data_Geotech[[#This Row],[Broken Core (m)]]+Data_Geotech[[#This Row],[Lost Core (m)]])*30,0),0) -> 0 | AC10: =IF(Data_Geotech[[#This Row],[Added fractures (BC, FLT, LC)]]+Data_Geotech[[#This Row],[Fracture per interval]]=0,99,1/((Data_Geotech[[#This Row],[Fracture per interval]]+Data_Geotech[[#This Row],[Added fractures (BC, FLT, LC)]])/Data_Geotech[[#This Row],[Run (m)]])) -> 99 | AD10: {=IFERROR(_xlfn.XLOOKUP(1,(A10=PLT!$A$4:$A$8886)*(Geotech!C10<=PLT!$F$4:$F$8886)*(Geotech!D10>=PLT!$F$4:$F$8886)*("Valid"=PLT!$P$4:$P$8886),PLT!$V$4:$V$8886),"")} -> 0 | AE10: {=IFERROR(_xlfn.XLOOKUP(1,(A10=PLT!$A$4:$A$8886)*(Geotech!C10<=PLT!$F$4:$F$8886)*(Geotech!D10>=PLT!$F$4:$F$8886)*(PLT!$V$4:$V$8886<>AD10)*("Valid"=PLT!$P$4:$P$7190),PLT!$V$4:$V$8886),"")} | AF10: {=IFERROR(_xlfn.XLOOKUP(1,(A10=PLT!$A$4:$A$8886)*(Geotech!C10<=PLT!$F$4:$F$8886)*(Geotech!D10>=PLT!$F$4:$F$8886)*(PLT!$V$4:$V$8886<>AD10)*(PLT!$V$4:$V$8886<>AE10)*("Valid"=PLT!$P$4:$P$7190),PLT!$V$4:$V$8886),"")} | AG10: =IFERROR(IF(AVERAGE(AD10:AF10)>References!$BO$23,References!$BP$23, IF(AVERAGE(AD10:AF10)>References!$BO$22,References!$BP$22, IF(AVERAGE(AD10:AF10)>References!$BO$21,References!$BP$21, IF(AVERAGE(AD10:AF10)>References!$BO$20,References!$BP$20, IF(AVERAGE(AD10:AF10)>References!$BO$19,References!$BP$19, IF(AVERAGE(AD10:AF10)>References!$BO$18,References!$BP$18, 0)))))),"") -> 0 | AH10: =IF(Data_Geotech[[#This Row],[Is50]]="",VLOOKUP(Data_Geotech[[#This Row],[Field Intact Rock Strength]],Table_RMR76_Strength[],2,FALSE),Data_Geotech[[#This Row],[Is50]]) -> 0 | AI10: =IF(Data_Geotech[[#This Row],[RQD (%)]]<=25,3,IF(Data_Geotech[[#This Row],[RQD (%)]]<=50,8,IF(Data_Geotech[[#This Row],[RQD (%)]]<=75,13,IF(Data_Geotech[[#This Row],[RQD (%)]]<=90,17,20)))) -> 20 | AJ10: =IF(Data_Geotech[[#This Row],[Joint spacing (m)]]<=0.05,5,IF(Data_Geotech[[#This Row],[Joint spacing (m)]]<=0.3,10,IF(Data_Geotech[[#This Row],[Joint spacing (m)]]<=1,20,IF(Data_Geotech[[#This Row],[Joint spacing (m)]]<=3,25,30)))) -> 30 | AK10: =IFERROR(AVERAGEIFS(Data_Discontinuities[[#All],[JCR]],Data_Discontinuities[[#All],[Hole ID]],"="&Data_Geotech[[#This Row],[Hole ID]],Data_Discontinuities[[#All],[Depth (m)]],">="&Data_Geotech[[#This Row],[From (m)]],Data_Discontinuities[[#All],[Depth (m)]],"<"&Data_Geotech[[#This Row],[To (m)]]),IF(Data_Geotech[[#This Row],[Added fractures (BC, FLT, LC)]]=0,IF(Data_Geotech[[#This Row],[Fracture per interval]]=0,25,6),6)) -> 25 | AL10: 10 | AM10: =IF(Data_Geotech[[#This Row],[FIRS Code]]="R",IFERROR(SUM(Data_Geotech[[#This Row],[RMR76 - Strength rating]:[RMR76 - Ground water rating]]),""),"") -> 85 | AN10: =IF(Data_Geotech[[#This Row],[FIRS Code]]="R",(2*Data_Geotech[[#This Row],[RMR76 - Joint condition rating]])+(IF(Data_Geotech[[#This Row],[RQD (%)]]>80,80/2,Data_Geotech[[#This Row],[RQD (%)]]/2)),"") -> 90 | AO10: =LEFT(Data_Geotech[[#This Row],[Joint Set Rating]],FIND("-",Data_Geotech[[#This Row],[Joint Set Rating]],1)-2) -> 0.5 | AP10: =IFERROR(AVERAGEIFS(Data_Discontinuities[[#All],[Jr/Ja]],Data_Discontinuities[[#All],[Hole ID]],"="&Data_Geotech[[#This Row],[Hole ID]],Data_Discontinuities[[#All],[Depth (m)]],">="&Data_Geotech[[#This Row],[From (m)]],Data_Discontinuities[[#All],[Depth (m)]],"<"&Data_Geotech[[#This Row],[To (m)]]),IF(Data_Geotech[[#This Row],[Added fractures (BC, FLT, LC)]]>Data_Geotech[[#This Row],[Fracture per interval]],1/4,IF(Data_Geotech[[#This Row],[Fracture per interval]]=0,4/0.75,"ERROR: should never happen!"))) -> 5.3333333 | AQ10: =1/1 -> 1 | AR10: =IF(Data_Geotech[[#This Row],[FIRS Code]]="R",IFERROR((IF(Data_Geotech[[#This Row],[RQD (%)]]<10,10,Data_Geotech[[#This Row],[RQD (%)]])/Data_Geotech[[#This Row],[Jn rating]])*Data_Geotech[[#This Row],[Jr/Ja]],""),"") | AS10: =IF(Data_Geotech[[#This Row],[FIRS Code]]="R",IFERROR((IF(Data_Geotech[[#This Row],[RQD (%)]]<10,10,Data_Geotech[[#This Row],[RQD (%)]])/Data_Geotech[[#This Row],[Jn rating]])*Data_Geotech[[#This Row],[Jr/Ja]]*Data_Geotech[[#This Row],[Jw/SRF]],""),"") | AU10: =100-Data_Geotech[[#This Row],[RQD (%)]] -> 0 | AV10: =100-Data_Geotech[[#This Row],[TCR (%)]] -> -1.7053026e-13 | AW10: =(Data_Geotech[[#This Row],[Fracture per interval]]+Data_Geotech[[#This Row],[Added fractures (BC, FLT, LC)]])/Data_Geotech[[#This Row],[TCR (m)]] -> 0 | AX10: R | AY10: =7-MID(Data_Geotech[[#This Row],[Field Intact Rock Strength]],2,1) -> 1 | AZ10: =VLOOKUP(Data_Geotech[[#This Row],[Field Intact Rock Strength]],Table_FieldStrength[],2,FALSE) -> 250 | BA10: =VLOOKUP(Data_Geotech[[#This Row],[Field Intact Rock Strength]],Table_FieldStrength[],3,FALSE) -> 275 | BB10: =VLOOKUP(Data_Geotech[[#This Row],[Field Intact Rock Strength]],Table_FieldStrength[],4,FALSE) -> 300 | BC10: =100-Data_Geotech[[#This Row],[RMR76]] -> 15 | BD10: =LEFT(Data_Geotech[[#This Row],[Weathering/Alteration]],FIND("-",Data_Geotech[[#This Row],[Weathering/Alteration]])-2) -> W1/A1
